Workbook

Sheet kategori
A1: nama_perk | B1: kode_perk | C1: parent | D1: level
A2: ISOLASI | B2: 15.01 | C2: 15 | D2: 2
A3: ISOLASI TAHAN PANAS | B3: 15.01.01 | C3: 15.01 | D3: 3
A4: FABRIC | B4: 15.02 | C4: 15 | D4: 2
A5: PTFE COATED FABRIC | B5: 15.02.01 | C5: 15.02 | D5: 3
A6: PTFE COATED GLASS | B6: 15.02.02 | C6: 15.02 | D6: 3
A7: DOUBLE TAPE | B7: 15.03 | C7: 15 | D7: 2
A8: DOUBLE TAPE NITTO | B8: 15.03.01 | C8: 15.03 | D8: 3
A9: DOUBLE TAPE | B9: 15.03.02 | C9: 15.03 | D9: 3
A10: AFT SCAPA | B10: 15.03.03 | C10: 15.03 | D10: 3
A11: fabric with adeshive | B11: 15.04 | C11: 15 | D11: 2
A12: PTFE COATED FABRIC WITH ADESHIVE | B12: 15.04.01 | C12: 15.04 | D12: 3
A13: accecoris op mesh | B13: 15.05 | C13: 15 | D13: 2
... A112: TIMING BELT | B112: 15.25.02 | C112: 15.25 | D112: 3

Sheet item_barang
A1: ISOLASI | B1: SG25T03-8mm | C1: ISOLASI TAHAN PANAS | D1: 15.01.01
B2: SG25T03-10mm | C2: ISOLASI TAHAN PANAS
B3: SG25T03-13mm | C3: ISOLASI TAHAN PANAS
B4: SG25T03-19mm | C4: ISOLASI TAHAN PANAS
B5: SG25T03-20mm | C5: ISOLASI TAHAN PANAS
B6: SG25T03-25mm | C6: ISOLASI TAHAN PANAS
B7: SG25T03-30mm | C7: ISOLASI TAHAN PANAS
B8: SG25T03-40mm | C8: ISOLASI TAHAN PANAS
B9: SG25T03-50mm | C9: ISOLASI TAHAN PANAS
B10: SG25T03-60mm | C10: ISOLASI TAHAN PANAS
B11: SG25T03-100mm | C11: ISOLASI TAHAN PANAS
B12: SG25T03- 1000mm | C12: ISOLASI TAHAN PANAS
B13: SG25T05-500MM | C13: ISOLASI TAHAN PANAS
B14: SG25T05-50MM | C14: ISOLASI TAHAN PANAS
A16: ISOLASI | B16: N973UL-8 | C16: ISOLASI TAHAN PANAS
B17: N973UL-10 | C17: ISOLASI TAHAN PANAS
B18: N973UL-13 | C18: ISOLASI TAHAN PANAS
B19: N973UL-19 | C19: ISOLASI TAHAN PANAS
B20: N973UL-25 | C20: ISOLASI TAHAN PANAS
B21: N973UL-30 | C21: ISOLASI TAHAN PANAS
B22: N973UL-50 | C22: ISOLASI TAHAN PANAS
B23: N973UL-300 | C23: ISOLASI TAHAN PANAS
B24: N973UL-600 | C24: ISOLASI TAHAN PANAS
A26: ISOLASI | B26: N903UL-13 | C26: ISOLASI TAHAN PANAS
B27: N903UL-19 | C27: ISOLASI TAHAN PANAS
B28: N903UL-25 | C28: ISOLASI TAHAN PANAS
B29: N903UL-50 | C29: ISOLASI TAHAN PANAS
A31: ISOLASI | B31: N923S-38 | C31: ISOLASI TAHAN PANAS
B32: N923S-50 | C32: ISOLASI TAHAN PANAS
A34: ISOLASI | B34: N973UL-13 D | C34: ISOLASI TAHAN PANAS
B35: N973UL-19 D | C35: ISOLASI TAHAN PANAS
B36: N973UL-25 D | C36: ISOLASI TAHAN PANAS
B37: N973UL-50 D | C37: ISOLASI TAHAN PANAS
B38: N973 0.18-50 D | C38: ISOLASI TAHAN PANAS
A40: ISOLASI | B40: CHK AGF 100-10MM | C40: ISOLASI TAHAN PANAS
B41: CHK AGF 100-25MM | C41: ISOLASI TAHAN PANAS
B42: CHK AGF 100-50MM | C42: ISOLASI TAHAN PANAS
B43: CHK ASF 110-50MM | C43: ISOLASI TAHAN PANAS
B44: CHK ASF 110-250MM | C44: ISOLASI TAHAN PANAS
B45: CHK AGF 0.13-25MM | C45: ISOLASI TAHAN PANAS
...

Sheet item_inv
A1: kode_perk | B1: kode_barang | C1: uraian | D1: qty | E1: satuan | F1: harga | G1: total
A2: =VLOOKUP(item_inv!C2,kategori!$A$2:$B$121,2,FALSE) -> 15.01.01 | B2: SG25T03-8mm | C2: ISOLASI TAHAN PANAS | D2: 78 | E2: RL | F2: 24409.78 | G2: 1903962.8
A3: =VLOOKUP(item_inv!C3,kategori!$A$2:$B$121,2,FALSE) -> 15.01.01 | B3: SG25T03-10mm | C3: ISOLASI TAHAN PANAS | D3: 108 | E3: RL | F3: 30341.33 | G3: 3276863.6
A4: =VLOOKUP(item_inv!C4,kategori!$A$2:$B$121,2,FALSE) -> 15.01.01 | B4: SG25T03-13mm | C4: ISOLASI TAHAN PANAS | D4: 132 | E4: RL | F4: 39264.64 | G4: 5182932.5
A5: =VLOOKUP(item_inv!C5,kategori!$A$2:$B$121,2,FALSE) -> 15.01.01 | B5: SG25T03-19mm | C5: ISOLASI TAHAN PANAS | D5: 99 | E5: RL | F5: 56965.24 | G5: 5639558.8
A6: =VLOOKUP(item_inv!C6,kategori!$A$2:$B$121,2,FALSE) -> 15.01.01 | B6: SG25T03-20mm | C6: ISOLASI TAHAN PANAS | D6: 6 | E6: RL | F6: 64841.98 | G6: 389051.88
A7: =VLOOKUP(item_inv!C7,kategori!$A$2:$B$121,2,FALSE) -> 15.01.01 | B7: SG25T03-25mm | C7: ISOLASI TAHAN PANAS | D7: 44 | E7: RL | F7: 74995.91 | G7: 3299820
A8: =VLOOKUP(item_inv!C8,kategori!$A$2:$B$121,2,FALSE) -> 15.01.01 | B8: SG25T03-30mm | C8: ISOLASI TAHAN PANAS | D8: 0 | E8: RL | F8: 97283.68 | G8: 0
A9: =VLOOKUP(item_inv!C9,kategori!$A$2:$B$121,2,FALSE) -> 15.01.01 | B9: SG25T03-40mm | C9: ISOLASI TAHAN PANAS | D9: 0 | E9: RL | F9: 0 | G9: 0
A10: =VLOOKUP(item_inv!C10,kategori!$A$2:$B$121,2,FALSE) -> 15.01.01 | B10: SG25T03-50mm | C10: ISOLASI TAHAN PANAS | D10: 40 | E10: RL | F10: 150271.06 | G10: 6010842.4
A11: =VLOOKUP(item_inv!C11,kategori!$A$2:$B$121,2,FALSE) -> 15.01.01 | B11: SG25T03-60mm | C11: ISOLASI TAHAN PANAS | D11: 0 | E11: RL | F11: 0 | G11: 0
A12: =VLOOKUP(item_inv!C12,kategori!$A$2:$B$121,2,FALSE) -> 15.01.01 | B12: SG25T03-100mm | C12: ISOLASI TAHAN PANAS | D12: 0 | E12: RL | F12: 0 | G12: 0
A13: =VLOOKUP(item_inv!C13,kategori!$A$2:$B$121,2,FALSE) -> 15.01.01 | B13: SG25T03- 1000mm | C13: ISOLASI TAHAN PANAS | D13: 210 | E13: RL | F13: 3031087 | G13: 636528270
... A94: =VLOOKUP(item_inv!C94,kategori!$A$2:$B$121,2,FALSE) -> 15.02.01 | B94: TF 610 RS | C94: PTFE COATED FABRIC | D94: 315 | E94: ML | F94: 60529.76 | G94: 19066874
A95: =VLOOKUP(item_inv!C95,kategori!$A$2:$B$121,2,FALSE) -> 15.02.01 | B95: TF 618 RS | C95: PTFE COATED FABRIC | D95: 195 | F95: 93320.21 | G95: 18197441
A96: =VLOOKUP(item_inv!C96,kategori!$A$2:$B$121,2,FALSE) -> 15.02.01 | B96: TF 910 P | C96: PTFE COATED FABRIC | D96: 336.6 | E96: ML | F96: 40217 | G96: 13537042
A97: =VLOOKUP(item_inv!C97,kategori!$A$2:$B$121,2,FALSE) -> 15.02.01 | B97: TF 910P-10ML | C97: PTFE COATED FABRIC | D97: 1 | E97: RL | F97: 563736.4 | G97: 563736.4
A98: =VLOOKUP(item_inv!C98,kategori!$A$2:$B$121,2,FALSE) -> 15.02.01 | B98: TF 910A | C98: PTFE COATED FABRIC | D98: 315 | E98: ML | F98: 58652 | G98: 18475380
A99: =VLOOKUP(item_inv!C99,kategori!$A$2:$B$121,2,FALSE) -> 15.02.01 | B99: TF 920 P | C99: PTFE COATED FABRIC | D99: 419 | E99: ML | F99: 92342 | G99: 38691298
A100: =VLOOKUP(item_inv!C100,kategori!$A$2:$B$121,2,FALSE) -> 15.02.01 | B100: TF 613 RS | C100: PTFE COATED FABRIC | D100: 419.6 | E100: ML | F100: 74366 | G100: 31203974
A101: =VLOOKUP(item_inv!C101,kategori!$A$2:$B$121,2,FALSE) -> 15.02.01 | B101: TF 613 RS-10ML | C101: PTFE COATED FABRIC | D101: 1 | E101: RL | F101: 977973 | G101: 977973
A102: =VLOOKUP(item_inv!C102,kategori!$A$2:$B$121,2,FALSE) -> 15.02.01 | B102: TF 615 RS | C102: PTFE COATED FABRIC | D102: 107 | E102: ML | F102: 113816.1 | G102: 12178323
A103: =VLOOKUP(item_inv!C103,kategori!$A$2:$B$121,2,FALSE) -> 15.02.01 | B103: N970-2-0.05 | C103: PTFE COATED FABRIC | D103: 20 | E103: ML | F103: 143140 | G103: 2862800
A104: =VLOOKUP(item_inv!C104,kategori!$A$2:$B$121,2,FALSE) -> 15.02.01 | B104: N970-2-0.07 | C104: PTFE COATED FABRIC | D104: 5 | E104: RL | F104: 3650818.4 | G104: 18254092
A105: =VLOOKUP(item_inv!C105,kategori!$A$2:$B$121,2,FALSE) -> 15.02.01 | B105: N970-2-0.10 | C105: PTFE COATED FABRIC | D105: 1 | E105: RL | F105: 3533805.4 | G105: 3533805.4
A106: =VLOOKUP(item_inv!C106,kategori!$A$2:$B$121,2,FALSE) -> 15.02.01 | B106: N970-2-0.10-MTR | C106: PTFE COATED FABRIC | D106: 5.3 | E106: ML | F106: 339215 | G106: 1797839.5
A107: =VLOOKUP(item_inv!C107,kategori!$A$2:$B$121,2,FALSE) -> 15.02.01 | B107: NSRGC-R10 | C107: PTFE COATED FABRIC | D107: 7 | E107: RL | F107: 1 | G107: 0
... A121: =VLOOKUP(item_inv!C121,kategori!$A$2:$B$121,2,FALSE) -> 15.04.01 | B121: CS 205S-10ML | C121: PTFE COATED FABRIC WITH ADESHIVE | D121: 1 | E121: RL | F121: 1446434 | G121: 1446434
A122: =VLOOKUP(item_inv!C122,kategori!$A$2:$B$121,2,FALSE) -> 15.04.01 | B122: CS 410 | C122: PTFE COATED FABRIC WITH ADESHIVE | D122: 9.5 | E122: ML | F122: 1
A123: =VLOOKUP(item_inv!C123,kategori!$A$2:$B$121,2,FALSE) -> 15.05.01 | B123: BENANG BIRU-ROLL | C123: ACC OPEN MESH | D123: 1 | E123: RL | F123: 1406887 | G123: 1406887
A124: =VLOOKUP(item_inv!C124,kategori!$A$2:$B$121,2,FALSE) -> 15.05.01 | B124: BENANG BIRU - MTR NEW | C124: ACC OPEN MESH | D124: 100.14 | E124: ML | F124: 1607 | G124: 160924.98
A125: =VLOOKUP(item_inv!C125,kategori!$A$2:$B$121,2,FALSE) -> 15.05.01 | B125: BENANG NOMEX | C125: ACC OPEN MESH | D125: 2 | E125: RL | F125: 410795 | G125: 821590
A126: =VLOOKUP(item_inv!C126,kategori!$A$2:$B$121,2,FALSE) -> 15.05.01 | B126: BENANG NOMEX-MTR | C126: ACC OPEN MESH | D126: 1854 | E126: ML | F126: 206 | G126: 381924
A127: =VLOOKUP(item_inv!C127,kategori!$A$2:$B$121,2,FALSE) -> 15.05.01 | B127: BENANG KEV COKLAT | C127: ACC OPEN MESH | D127: 6 | E127: RL | F127: 462610 | G127: 2775660
A128: =VLOOKUP(item_inv!C128,kategori!$A$2:$B$121,2,FALSE) -> 15.05.01 | B128: BENANG KUNING -0.5 KG | C128: ACC OPEN MESH | D128: 9 | E128: RL | F128: 534006 | G128: 4806054
A129: =VLOOKUP(item_inv!C129,kategori!$A$2:$B$121,2,FALSE) -> 15.05.01 | B129: BENANG KUNING- 0.55kg | C129: ACC OPEN MESH | D129: 1 | E129: RL | F129: 649561 | G129: 649561
A130: =VLOOKUP(item_inv!C130,kategori!$A$2:$B$121,2,FALSE) -> 15.05.01 | B130: BENANG KUNING -MTR | C130: ACC OPEN MESH | D130: 0 | E130: ML | F130: 0 | G130: 0
A131: =VLOOKUP(item_inv!C131,kategori!$A$2:$B$121,2,FALSE) -> 15.05.01 | B131: BENANG KUNING SEALING | C131: ACC OPEN MESH | D131: 1909 | E131: ML | F131: 297.28 | G131: 567507.52
A132: =VLOOKUP(item_inv!C132,kategori!$A$2:$B$121,2,FALSE) -> 15.05.01 | B132: BENANG KUNING -MTR 0.72KG | C132: ACC OPEN MESH | D132: 135 | E132: ML | F132: 685.11 | G132: 92489.85
A133: =VLOOKUP(item_inv!C133,kategori!$A$2:$B$121,2,FALSE) -> 15.05.01 | B133: BENANG TEFLON WHITE-RL | C133: ACC OPEN MESH | D133: 0 | E133: RL | F133: 0 | G133: 0
...

Sheet Sheet2
B1: jenis barang | C1: Kode | D1: TYPE / | E1: Qty | F1: Satuan | G1: Harga | H1: TOTAL
A2: 1 | B2: ISOLASI | C2: SG25T03-8mm | D2: ISOLASI TAHAN PANAS | E2: 78 | F2: RL | G2: 24409.78 | H2: 1903962.8 | I2: ok
A3: 2 | C3: SG25T03-10mm | D3: ISOLASI TAHAN PANAS | E3: 108 | F3: RL | G3: 30341.33 | H3: 3276863.6 | I3: ok
A4: 3 | C4: SG25T03-13mm | D4: ISOLASI TAHAN PANAS | E4: 132 | F4: RL | G4: 39264.64 | H4: 5182932.5 | I4: ok
A5: 4 | C5: SG25T03-19mm | D5: ISOLASI TAHAN PANAS | E5: 99 | F5: RL | G5: 56965.24 | H5: 5639558.8 | I5: ok
A6: 5 | C6: SG25T03-20mm | D6: ISOLASI TAHAN PANAS | E6: 6 | F6: RL | G6: 64841.98 | H6: 389051.88 | I6: ok
A7: 6 | C7: SG25T03-25mm | D7: ISOLASI TAHAN PANAS | E7: 44 | F7: RL | G7: 74995.91 | H7: 3299820 | I7: ok
A8: 7 | C8: SG25T03-30mm | D8: ISOLASI TAHAN PANAS | E8: 0 | F8: RL | G8: 97283.68 | H8: 0
A9: 8 | C9: SG25T03-40mm | D9: ISOLASI TAHAN PANAS | E9: 0 | F9: RL | H9: 0
A10: 9 | C10: SG25T03-50mm | D10: ISOLASI TAHAN PANAS | E10: 40 | F10: RL | G10: 150271.06 | H10: 6010842.4 | I10: ok
A11: 10 | C11: SG25T03-60mm | D11: ISOLASI TAHAN PANAS | E11: 0 | F11: RL | H11: 0
A12: 11 | C12: SG25T03-100mm | D12: ISOLASI TAHAN PANAS | E12: 0 | F12: RL | H12: 0
A13: 12 | C13: SG25T03- 1000mm | D13: ISOLASI TAHAN PANAS | E13: 210 | F13: RL | G13: 3031087 | H13: 636528270 | I13: ok
A14: 13 | C14: SG25T05-500MM | D14: ISOLASI TAHAN PANAS | E14: 2 | F14: RL | G14: 3066199 | H14: 6132398 | I14: ok
A15: 14 | C15: SG25T05-50MM | D15: ISOLASI TAHAN PANAS | E15: 1 | F15: RL | G15: 306620 | H15: 306620 | I15: ok
A16: 15 | B16: ISOLASI | C16: N973UL-8 | D16: ISOLASI TAHAN PANAS | E16: 5 | F16: RL | G16: 24370.5 | H16: 121852.5 | I16: ok
A17: 16 | C17: N973UL-10 | D17: ISOLASI TAHAN PANAS | E17: 44 | F17: RL | G17: 35199 | H17: 1548756 | I17: ok
A18: 17 | C18: N973UL-13 | D18: ISOLASI TAHAN PANAS | E18: 114 | F18: RL | G18: 46304.18 | H18: 5278676.5 | I18: ok
A19: 18 | C19: N973UL-19 | D19: ISOLASI TAHAN PANAS | E19: 16 | F19: RL | G19: 67008.74 | H19: 1072139.8 | I19: ok
A20: 19 | C20: N973UL-25 | D20: ISOLASI TAHAN PANAS | E20: 45 | F20: RL | G20: 88136.82 | H20: 3966156.9 | I20: ok
A21: 20 | C21: N973UL-30 | D21: ISOLASI TAHAN PANAS | E21: 0 | F21: RL | H21: 0
A22: 21 | C22: N973UL-50 | D22: ISOLASI TAHAN PANAS | E22: 9 | F22: RL | G22: 133976.68 | H22: 1205790.1 | I22: ok
A23: 22 | C23: N973UL-300 | D23: ISOLASI TAHAN PANAS | E23: 1 | F23: RL | G23: 1139549 | H23: 1139549 | I23: ok
A24: 23 | C24: N973UL-600 | D24: ISOLASI TAHAN PANAS | E24: 17 | F24: RL | G24: 2185436 | H24: 37152412 | I24: ok
A25: 24 | B25: ISOLASI | C25: N903UL-13 | D25: ISOLASI TAHAN PANAS | E25: 538 | F25: RL | G25: 55113 | H25: 29650794 | I25: ok
A26: 25 | C26: N903UL-19 | D26: ISOLASI TAHAN PANAS | E26: 104 | F26: RL | G26: 80493 | H26: 8371272 | I26: ok
A27: 26 | C27: N903UL-25 | D27: ISOLASI TAHAN PANAS | E27: 0 | F27: RL | H27: 0
A28: 27 | C28: N903UL-50 | D28: ISOLASI TAHAN PANAS | E28: 61 | F28: RL | G28: 210264 | H28: 12826104 | I28: ok
A29: 28 | B29: ISOLASI | C29: N923S-38 | D29: ISOLASI TAHAN PANAS | E29: 52 | F29: RL | G29: 1018374.1 | H29: 52955451 | I29: ok
A30: 29 | C30: N923S-50 | D30: ISOLASI TAHAN PANAS | E30: 32 | F30: RL | G30: 1129934 | H30: 36157889 | I30: ok
A31: 30 | B31: ISOLASI | C31: N973UL-13 D | D31: ISOLASI TAHAN PANAS | E31: 462 | F31: RL | G31: 56967.16 | H31: 26318828 | I31: ok
A32: 31 | C32: N973UL-19 D | D32: ISOLASI TAHAN PANAS | E32: 196 | F32: RL | G32: 81702.88 | H32: 16013764 | I32: ok
A33: 32 | C33: N973UL-25 D | D33: ISOLASI TAHAN PANAS | E33: 290 | F33: RL | G33: 107996.06 | H33: 31318857 | I33: ok
A34: 33 | C34: N973UL-50 D | D34: ISOLASI TAHAN PANAS | E34: 18 | F34: RL | G34: 183206.12 | H34: 3297710.2 | I34: ok
A35: 34 | C35: N973 0.18-50 D | D35: ISOLASI TAHAN PANAS | E35: 115 | F35: RL | G35: 301099.23 | H35: 34626411 | I35: ok
A36: 35 | B36: ISOLASI | C36: CHK AGF 100-10MM | D36: ISOLASI TAHAN PANAS | E36: 376 | F36: RL | G36: 54791.08 | H36: 20601446 | I36: ok
A37: 36 | C37: CHK AGF 100-25MM | D37: ISOLASI TAHAN PANAS | E37: 155 | F37: RL | G37: 136907.12 | H37: 21220604 | I37: ok
A38: 37 | C38: CHK AGF 100-50MM | D38: ISOLASI TAHAN PANAS | E38: 228 | F38: RL | G38: 272189.33 | H38: 62059167 | I38: ok
A39: 38 | C39: CHK ASF 110-50MM | D39: ISOLASI TAHAN PANAS | E39: 186 | F39: RL | G39: 281746 | H39: 52404756 | I39: ok
A40: 39 | C40: CHK ASF 110-250MM | D40: ISOLASI TAHAN PANAS | E40: 11 | F40: RL | G40: 1427360.1 | H40: 15700961 | I40: ok
...
